Workbook

Sheet Summary
A3: Bills received from service provider
A4: Inv.No. | B4: Inv.Date | C4: Month | D4: Service from Dt. | E4: To Date | F4: Amount | G4: Hamali | H4: Total Amount | I4: Amount cleared | J4: Date | K4: Remarks
A5: Nil | D5: 01.04.2025 | E5: 30.04.2025 | H5: 340800 | I5: 340800
A21: Bills Submitted to IIL
A22: Inv.No. | B22: Inv.Date | C22: Month | D22: Service from Dt. | E22: To Date | F22: Amount | G22: Hamali | H22: Total Amount | I22: Amount cleared | J22: Date | K22: Remarks
A23: IIL/04/2025-26-001 | B23: 15.04.2025 | C23: April | D23: 01.4.25 | E23: 15.04.25 | F23: 134600 | G23: 58800 | H23: =G23+F23 -> 193400
A24: IIL/04/2025-26-002 | B24: 30.04.25 | C24: April | D24: 16.04.25 | E24: 30.04.25 | F24: 165800 | G24: 84000 | H24: =G24+F24 -> 249800
A25: IIL/05/2025-26-001 | B25: 10.05.25 | C25: May | D25: 01.05.25 | E25: 10.05.25 | F25: 138700 | G25: 63600 | H25: =G25+F25 -> 202300
A26: IIL/05/2025-26-002 | B26: 20.05.25 | C26: May | D26: 11.05.25 | E26: 20.05.25 | F26: 108300 | G26: 44400 | H26: =G26+F26 -> 152700
A27: IIL/05/2025-26-003 | B27: 31.05.25 | C27: May | D27: 21.05.25 | E27: 31.05.25 | F27: 165900 | G27: 76800 | H27: =G27+F27 -> 242700
A28: IIL/06/2025-26-001 | B28: 15.06.25 | C28: June | D28: 01.06.25 | E28: 14.06.25 | F28: 192600 | G28: 93600 | H28: =G28+F28 -> 286200
A29: IIL/06/2025-26-002 | B29: 30.06.26 | C29: June | D29: 15.06.25 | E29: 30.06.25 | F29: 255300 | G29: 126000 | H29: =G29+F29 -> 381300
A30: IIL/07/2025-26-001 | B30: 15.07.25 | C30: July | D30: 01.07.25 | E30: 15.07.25 | F30: 231800 | G30: 105600 | H30: =G30+F30 -> 337400
A31: IIL/07/2025-26-002 | B31: 31.07.25 | C31: July | D31: 16.07.25 | E31: 31.07.25 | F31: 330600 | G31: 148600 | H31: =G31+F31 -> 479200
A32: IIL/08/2025-26-001 | B32: 15.08.25 | C32: Aug | D32: 01.08.25 | E32: 15.08.25 | F32: 251700 | G32: 113600 | H32: =G32+F32 -> 365300
A33: IIL/08/2025-26-002 | B33: 01.09.25 | C33: Sept | D33: 16.08.25 | E33: 31.08.25 | F33: 400400 | G33: 188800 | H33: 588000 | I33: 588000
A34: IIL/09/2025-26-001 | B34: 15.09.25 | C34: Sept | D34: 01.09.25 | E34: 15.09.25 | F34: 306600 | G34: 144000 | H34: 440902 | I34: 440902
A35: IIL/09/2025-26-002 | B35: 30.09.25 | C35: Sept | D35: 16.09.25 | E35: 30.09.25 | F35: 313000 | G35: 146200 | H35: 458469 | I35: 449300 | J35: =H35-I35 -> 9169
A36: IIL/10/2025-26-001 | B36: 15.10.25 | C36: Oct | D36: 01.10.25 | E36: 15.10.25 | F36: 199300 | G36: 100200 | H36: 301600 | I36: 295568 | J36: =H36-I36 -> 6032
A37: IIL/10/2025-26-002 | B37: 31.10.25 | C37: Oct | D37: 16.10.25 | E37: 31.10.25 | F37: 233000 | G37: 120000 | H37: 346000 | I37: 339080
A38: IIL/11/2025-26-001 | B38: 16.11.25 | C38: Nov | D38: 01.11.25 | E38: 15.11.25 | F38: 177500 | G38: 88200 | H38: =G38+F38 -> 265700
A39: IIL/11/2025-26-002 | B39: 01.12.25 | C39: Nov | D39: 16.11.25 | E39: 30.11.25 | F39: 210500 | G39: 101400 | H39: =G39+F39 -> 311900
A40: IIL/12/2025-26-001 | B40: 15.12.25 | C40: Dec | D40: 01.12.25 | E40: 15.12.25 | F40: 409300 | G40: 189700 | H40: =G40+F40 -> 599000
A41: IIL/12/2025-26-002 | B41: 31.12.25 | C41: Dec | D41: 16.12.25 | E41: 31.12.25 | F41: 257100 | G41: 116400 | H41: =G41+F41 -> 373500
A42: IIL/01/2026-001 | B42: 15.01.26 | C42: Jan | D42: 01.01.26 | E42: 15.01.26 | F42: 178400 | G42: 78600 | H42: =G42+F42 -> 257000
A43: IIL/02/2026-001 | B43: 31.01.26 | C43: Jan | D43: 16.01.26 | E43: 31.01.26 | F43: 514600 | G43: 241800 | H43: =G43+F43 -> 756400
D45: Total | F45: =SUM(F23:F44) -> 5175000 | G45: =SUM(G23:G44) -> 2430300 | H45: =SUM(H23:H44) -> 7588771
A48: Payment receipts from IIL
A50: Date | B50: Amount
A51: 20.05.25 | B51: 189532 | C51: =H23 -> 193400 | D51: =C51-B51 -> 3868 | E51: =D51/C51 -> 0.02
A52: 30.05.25 | B52: 443058 | C52: 452100 | D52: =C52-B52 -> 9042 | E52: =D52/C52 -> 0.02 | G52: 452100 | H52: =G52-B52 -> 9042 | I52: =H52/G52 -> 0.02
A53: 23.06.25 | B53: 149646 | C53: =H26 -> 152700 | D53: =C53-B53 -> 3054 | E53: =D53/C53 -> 0.02
A54: 02.07.25 | B54: 237846 | C54: =H27 -> 242700 | D54: =C54-B54 -> 4854 | E54: =D54/C54 -> 0.02
A55: 16.07.25 | B55: 280476 | C55: =H28 -> 286200 | D55: =C55-B55 -> 5724 | E55: =D55/C55 -> 0.02
A56: 04.08.25 | B56: 373674 | C56: =H29 -> 381300 | D56: =C56-B56 -> 7626 | E56: =D56/C56 -> 0.02
A57: 25.08.25 | B57: 330652 | C57: =H30 -> 337400 | D57: =C57-B57 -> 6748 | E57: =D57/C57 -> 0.02
A58: 12.09.25 | B58: 469616 | C58: =H31 -> 479200 | D58: =C58-B58 -> 9584 | E58: =D58/C58 -> 0.02 | H58: =D58/B58 -> 0.020408163 | I58: =B58*H58 -> 9584
A59: 25.09.25 | B59: 357994 | C59: =H32 -> 365300 | D59: =C59-B59 -> 7306 | E59: =D59/C59 -> 0.02 | H59: =D59/B59 -> 0.020408163 | I59: =B59*H59 -> 7306
A60: 29.10.25 | B60: 1028902 | C60: 588000 | D60: =B60*H59 -> 20998 | E60: =D60/(C60+C61) -> 0.020408163 | G60: 925600 | H60: =G60-B60 -> -103302 | I60: =H60/G60 -> -0.11160545 | K60: 2037300 | L60: 2112880 | M60: =L60-K60 -> 75580
A61: 10.11.25 | B61: 449330 | C61: 440902 | G61: 459500 | H61: =G61-B61 -> 10170 | I61: =H61/G61 -> 0.022132753 | M61: =M60/L60 -> 0.03577108
...

Sheet invoice
B2: SLN logistics
B3: Office:1-5-1115/506, Flat no.304, Panchasheel Enclave, Old Alwal – 5000010, GST NO. 36EGSPD7615E1Z8, Mobile:9396673734
B5: Tax Invoice
B6: To | J6: Inv. No. | K6: IIL/04/2025-26-001
B7: M/s.Indian Immunologicals Limited | J7: Inv. Dt | K7: 15.04.2025
B8: Rakshapuram, Gachibowli
B9: Hyderabad, Telangana
B10: GST No. | C10: 36AAAC16620F1ZV
B11: Place of Supply: Telangana
B12: Bill particulars | K12: Amount | L12: GST | M12: Total Amount
B14: Transportation service for the period of 01.04.2025 to 15.04.2025 | K14: 193400 | L14: 0 | M14: 193400
D16: as per the particulars attached
I20: Total | K20: 193400 | L20: - | M20: 193400 | P20: =+M20*2% -> 3868 | Q20: =+M20-P20 -> 189532
B22: Remarks: | C22: The recipient is liable to pay GST under reverse charge mechanism as per notification no.13/2017 – Central Tax ( Rate) dated 28th June 2017
L26: for SLN Logistics
L29: Authorised Signatory
B33: SLN logistics
B34: Office:1-5-1115/506, Flat no.304, Panchasheel Enclave, Old Alwal – 5000010, GST NO. 36EGSPD7615E1Z8, Mobile:9396673734
B36: Tax Invoice
B37: To | J37: Inv. No. | K37: IIL/04/2025-26-002
B38: M/s.Indian Immunologicals Limited | J38: Inv. Dt | K38: 30.04.2025
B39: Rakshapuram, Gachibowli
B40: Hyderabad, Telangana
B41: GST No. | C41: 36AAAC16620F1ZV
B42: Place of Supply: Telangana
B43: Bill particulars | K43: Amount | L43: GST | M43: Total Amount
B45: Transportation service for the period of 16.04.2025 to 30.04.2025 | K45: 249800 | L45: 0 | M45: 249800
D47: as per the particulars attached
I51: Total | K51: 249800 | L51: - | M51: 249800 | P51: =+M51*2% -> 4996 | Q51: =+M51-P51 -> 244804
B53: Remarks: | C53: The recipient is liable to pay GST under reverse charge mechanism as per notification no.13/2017 – Central Tax ( Rate) dated 28th June 2017 | Q53: =+Q51+Q20 -> 434336
Q54: =183200+134500-3900 -> 313800 | R54: sudhakar | S54: 327300 | T54: =+S54-Q54 -> 13500
Q55: =9600+3900 -> 13500 | R55: sonu | S55: 134500 | T55: labour
Q56: =+Q55+Q54 -> 327300 | S56: =183200+9600 -> 192800 | T56: vehicles
L57: for SLN Logistics | Q57: =+Q53-Q56 -> 107036 | S57: =+S56+S55 -> 327300
L60: Authorised Signatory
B63: SLN logistics
B64: Office:1-5-1115/506, Flat no.304, Panchasheel Enclave, Old Alwal – 5000010, GST NO. 36EGSPD7615E1Z8, Mobile:9396673734
B66: Tax Invoice
B67: To | J67: Inv. No. | K67: IIL/05/2025-26-001
B68: M/s.Indian Immunologicals Limited | J68: Inv. Dt | K68: 10.05.2025
...

Sheet April'25
A1: Trip particulars ( 01.04.2025 to 15.04.2025) | P1: Approx
A2: S.No. | B2: Date | C2: From Location | D2: To location | E2: NO OF BOXES | F2: Vehicle No | G2: Gross weight | H2: Volumetric weight | I2: Weight in Tons | J2: Chargeable weight | K2: Rate | L2: Hamali | M2: Total freight | N2: Hamali members | O2: Previous rate | P2: hamali | Q2: Total | R2: Remarks
A3: 1 | B3: 03.04.25 | C3: Priya feeds - Cherlapally | D3: IIL-Karkapatla | E3: 205 | F3: TS09VE2987 | G3: 4029.55 | H3: 3784.33 | I3: 4MT | J3: 6MT | K3: 7500 | L3: =1200*2 -> 2400 | M3: =+L3+K3 -> 9900 | N3: 2 members@1200 | O3: =5000+5000 -> 10000 | P3: =L3 -> 2400 | Q3: =+P3+O3 -> 12400 | R3: ealier party used to have only 3 ton capacity vehicle
A4: 2 | B4: 04.04.25 | C4: Priya feeds - Cherlapally | D4: IIL-Karkapatla | E4: 250 | F4: TS09VE2987 | G4: 5167 | H4: 2666.22 | I4: 5.17MT | J4: 6MT | K4: 7500 | L4: =1200*3 -> 3600 | M4: =+L4+K4 -> 11100 | N4: 3 members@1200 | O4: 5000 | P4: =L4 -> 3600 | Q4: =+P4+O4 -> 8600
A5: 3 | B5: 04.04.25 | C5: IIL-Karkapatla | D5: IIL-UPPAL | F5: AP28TA0092 | I5: 3MT | J5: 3MT | K5: 4900 | L5: =1200*2 -> 2400 | M5: =+L5+K5 -> 7300 | N5: 2 members@1200 | O5: 4200 | P5: =L5 -> 2400 | Q5: =+P5+O5 -> 6600 | V5: 6000 | W5: 5000
A6: 4 | B6: 07.04.25 | C6: Priya feeds - Cherlapally | D6: IIL-Karkapatla | E6: 344 | F6: TS06UA7249 | G6: 6165.71 | H6: 3550.3 | I6: 6.3MT | J6: 6MT | K6: 7500 | L6: =1200*3 -> 3600 | M6: =+L6+K6 -> 11100 | N6: 3 members@1200 | O6: =5000*2 -> 10000 | P6: =L6 -> 3600 | Q6: =+P6+O6 -> 13600 | R6: ealier party used to have only 3 ton capacity vehicle | V6: 5500 | W6: 5000
A7: 5 | B7: 07.04.25 | C7: Priya feeds - Cherlapally | D7: IIL-Karkapatla | E7: 344 | F7: AP28TA0092 | G7: 6165.71 | H7: 3550.3 | I7: 6MT | J7: 6MT | K7: 7500 | L7: =1200*3 -> 3600 | M7: =+L7+K7 -> 11100 | N7: 3 members@1200 | O7: =5000*2 -> 10000 | P7: =L7 -> 3600 | Q7: =+P7+O7 -> 13600 | R7: ealier party used to have only 3 ton capacity vehicle | V7: 5500 | W7: 5000
A8: 6 | B8: 07.04.25 | C8: Sanathnagr | D8: IIL-Karkapatla | F8: TG08T8450 | I8: 2MT | J8: 3MT | K8: 5200 | L8: 1200 | M8: =+L8+K8 -> 6400 | N8: 1 members@1200 | O8: 4700 | P8: =L8 -> 1200 | Q8: =+P8+O8 -> 5900 | V8: 3500 | W8: 3500
A9: 9 | B9: 07.04.25 | C9: IIL-Karkapatla | D9: IIL-UPPAL | F9: TG08T8450 | I9: 1MT | J9: 1MT | K9: 3500 | L9: 1200 | M9: =+L9+K9 -> 4700 | N9: 1 members@1200 | O9: 4200 | P9: =L9 -> 1200 | Q9: =+P9+O9 -> 5400 | V9: 3800 | W9: 3000
A10: 7 | B10: 07.04.25 | C10: SANZYME-KOLTHUR | D10: IIL-Gachibowli | F10: TG08T9023 | I10: 1MT | J10: 1MT | K10: 3500 | L10: 1200 | M10: =+L10+K10 -> 4700 | N10: 1 members@1200 | O10: 3750 | P10: =L10 -> 1200 | Q10: =+P10+O10 -> 4950 | V10: 4000 | W10: 3000
A11: 8 | B11: 07.04.25 | C11: IIL-Gachibowli | D11: IIL-UPPAL | F11: TG08T9023 | I11: 1MT | J11: 1MT | K11: 2900 | L11: 1200 | M11: =+L11+K11 -> 4100 | N11: 1 members@1200 | O11: 2300 | P11: =L11 -> 1200 | Q11: =+P11+O11 -> 3500 | V11: 4300 | W11: 3500
A12: 10 | B12: 08.04.25 | C12: Priya feeds - Cherlapally | D12: IIL-Karkapatla | E12: 344 | F12: TS06UA7249 | G12: 4914.46 | H12: 3493.19 | I12: 4.91MT | J12: 6MT | K12: 7500 | L12: 3600 | M12: =+L12+K12 -> 11100 | N12: 3 members @1200 | O12: =5000*2 -> 10000 | P12: =L12 -> 3600 | Q12: =+P12+O12 -> 13600 | R12: ealier party used to have only 3 ton capacity vehicle | V12: 5500 | W12: 5000
A13: 11 | B13: 09.04.25 | C13: Potential-ALEAP | D13: IIL-Karkapatla | E13: 340 | F13: TS06UA7249 | G13: 6258.7 | H13: 7693.7 | I13: 7.70MT | J13: 9MT | K13: 8500 | L13: =1200*4 -> 4800 | M13: =+L13+K13 -> 13300 | N13: 4 members @1200 | O13: =5000*3 -> 15000 | P13: =L13 -> 4800 | Q13: =+P13+O13 -> 19800 | R13: ealier party used to have only 3 ton capacity vehicle | V13: 5500 | W13: 5000
A14: 12 | B14: 09.04.25 | C14: IIL-UPPAL | D14: IIL-Karkapatla | F14: TG08T8450 | I14: 1MT | J14: 1MT | K14: 3500 | L14: 1200 | M14: =+L14+K14 -> 4700 | N14: 1 members@1200 | O14: 2800 | P14: =L14 -> 1200 | Q14: =+P14+O14 -> 4000 | V14: 2800 | W14: 2500
A15: 13 | B15: 10.04.25 | C15: Priya feeds - Cherlapally | D15: IIL-Karkapatla | E15: 374 | F15: TS06UA7249 | G15: 6615.7 | H15: 4741 | I15: 7.3MT | J15: 9MT | K15: 8500 | L15: 3600 | M15: =+L15+K15 -> 12100 | N15: 3 members @1200 | O15: =5000*3 -> 15000 | P15: =L15 -> 3600 | Q15: =+P15+O15 -> 18600 | R15: ealier party used to have only 3 ton capacity vehicle | V15: 5500 | W15: 5000
A16: 14 | B16: 10.04.25 | C16: Priya feeds - Cherlapally | D16: IIL-Karkapatla | E16: 375 | F16: TS12UB2595 | G16: 6615.7 | H16: 4741 | I16: 6MT | J16: 6MT | K16: 7500 | L16: 3600 | M16: =+L16+K16 -> 11100 | N16: 3 members @1200 | O16: =5000*2 -> 10000 | P16: =L16 -> 3600 | Q16: =+P16+O16 -> 13600 | R16: ealier party used to have only 3 ton capacity vehicle | V16: 5500 | W16: 5000
A17: 15 | B17: 11.04.25 | C17: Priya feeds - Cherlapally | D17: IIL-Karkapatla | E17: 366 | F17: TS06UA7249 | G17: 6198.3 | I17: 6.3MT | J17: 6MT | K17: 7500 | L17: 3600 | M17: =+L17+K17 -> 11100 | N17: 3 members @1200 | O17: =5000*2 -> 10000 | P17: =L17 -> 3600 | Q17: =+P17+O17 -> 13600 | R17: ealier party used to have only 3 ton capacity vehicle | V17: 5500 | W17: 5000
A18: 16 | B18: 11.04.25 | C18: Priya feeds - Cherlapally | D18: IIL-Karkapatla | E18: 367 | F18: TS12UB2595 | G18: 6198.3 | H18: 7868.1 | I18: 6MT | J18: 6MT | K18: 7500 | L18: 3600 | M18: =+L18+K18 -> 11100 | N18: 3 members @1200 | O18: =5000*2 -> 10000 | P18: =L18 -> 3600 | Q18: =+P18+O18 -> 13600 | R18: ealier party used to have only 3 ton capacity vehicle | V18: 5500 | W18: 5000
A19: 17 | B19: 11.04.25 | C19: Potential-ALEAP | D19: IIL-Karkapatla | E19: 199 | F19: TS09UC4067 | G19: 4330.24 | H19: 3330.52 | I19: 4.3MT | J19: 6MT | K19: 7500 | L19: 2400 | M19: =+L19+K19 -> 9900 | N19: 2 members @1200 | O19: =5000+4000 -> 9000 | P19: =L19 -> 2400 | Q19: =+P19+O19 -> 11400 | R19: ealier party used to have only 3 ton capacity vehicle | V19: 5500 | W19: 5000
A20: 18 | B20: 11.04.25 | C20: IIL-Gachibowli | D20: IIL-Karkapatla | F20: TG08T9023 | I20: 2MT | J20: 3MT | K20: 5600 | L20: 1200 | M20: =+L20+K20 -> 6800 | N20: 1 members @1200 | O20: 4700 | P20: =L20 -> 1200 | Q20: =+P20+O20 -> 5900 | V20: 4000 | W20: 3500
A21: 19 | B21: 14.04.25 | C21: Priya feeds - Cherlapally | D21: IIL-Karkapatla | F21: TS06UA7249 | G21: 6153 | H21: 4890 | I21: 6.2MT | J21: 6MT | K21: 7500 | L21: =1200*3 -> 3600 | M21: =+L21+K21 -> 11100 | N21: 3 members @1200 | O21: =5000*2 -> 10000 | P21: =L21 -> 3600 | Q21: =+P21+O21 -> 13600 | V21: 5500 | W21: 5000
A22: 20 | B22: 15.04.25 | C22: Gubba-Medchal | D22: Potential-ALEAP | F22: TS06UA7249 | G22: =6081.5+3000 -> 9081.5 | H22: =2535*2 -> 5070 | I22: 9MT | J22: 9MT | K22: 8500 | L22: =1200*4 -> 4800 | M22: =+L22+K22 -> 13300 | N22: 4 members @1200 | O22: 15000 | P22: =L22 -> 4800 | Q22: =+P22+O22 -> 19800 | V22: 5000 | W22: 4500
A23: 21 | B23: 15.04.25 | C23: Gubba-Medchal | D23: Potential-ALEAP | F23: TG08T8450 | G23: 3000 | I23: 3MT | J23: 3MT | K23: 5000 | L23: =1200*2 -> 2400 | M23: =+L23+K23 -> 7400 | N23: 2 members @1200 | O23: 5000 | P23: =L23 -> 2400 | Q23: =+P23+O23 -> 7400 | V23: 3000 | W23: 3000
J24: Total | K24: =SUM(K3:K23) -> 134600 | L24: =SUM(L3:L23) -> 58800 | M24: =SUM(M3:M23) -> 193400 | O24: =SUM(O3:O23) -> 170650 | P24: =SUM(P3:P23) -> 58800 | Q24: =SUM(Q3:Q23) -> 229450 | V24: =SUM(V3:V23) -> 91400 | W24: =SUM(W5:W23) -> 81500
K25: 78000 | L25: =+K24*10% -> 13460 | Q25: =Q24-M24 -> 36050
K26: =+K25+L25 -> 91460 | L26: =+K24-K26 -> 43140 | Q26: =+Q25/Q24 -> 0.15711484
A27: Trip particulars (16.04.2025 to 30.4.2025)
A28: S.No. | B28: Date | C28: From Location | D28: To location | E28: NO OF BOXES | F28: Vehicle No | G28: Gross weight | H28: Volumetric weight | I28: Weight in Tons | J28: Chargeable weight | K28: Rate | L28: Hamali | M28: Total freight | O28: Previous rate | P28: hamali | Q28: Total
A29: 1 | B29: 16.04.25 | C29: Priya feeds - Cherlapally | D29: IIL-Karkapatla | F29: TS06UA7249 | I29: 5MT | J29: 6MT | K29: 7500 | L29: 3600 | M29: =+L29+K29 -> 11100 | O29: =5000*2 -> 10000 | P29: 3600 | Q29: =+P29+O29 -> 13600 | V29: 5500
A30: 2 | B30: 16.04.25 | C30: IIL-Karkapatla | D30: IIL-UPPAL | F30: TS12UB2595 | I30: 4MT | J30: 6MT | K30: 5900 | L30: 3600 | M30: =+L30+K30 -> 9500 | O30: =5000*2 -> 10000 | P30: 3600 | Q30: =+P30+O30 -> 13600 | V30: 6000
A31: 3 | B31: 17.04.25 | C31: Gubba-Medchal | D31: Potential-ALEAP | F31: TS06UA7249 | I31: 9MT | J31: 9MT | K31: 8500 | L31: 4800 | M31: =+L31+K31 -> 13300 | O31: =5000*3 -> 15000 | P31: 4800 | Q31: =+P31+O31 -> 19800 | V31: 5000
A32: 4 | B32: 17.04.25 | C32: Gubba-Medchal | D32: Potential-ALEAP | F32: TG08T8450 | I32: 3MT | J32: 3MT | K32: 5000 | L32: 2400 | M32: =+L32+K32 -> 7400 | O32: 5000 | P32: 2400 | Q32: =+P32+O32 -> 7400 | V32: 3000
A33: 5 | B33: 17.04.25 | C33: Potential-ALEAP | D33: IIL-Karkapatla | F33: TS12UB2595 | I33: 5MT | J33: 6MT | K33: 7500 | L33: 3600 | M33: =+L33+K33 -> 11100 | O33: =5000*2 -> 10000 | P33: 3600 | Q33: =+P33+O33 -> 13600 | V33: 5000
A34: 6 | B34: 17.04.25 | C34: Potential-ALEAP | D34: IIL-Karkapatla | F34: TS12UC3042 | I34: 5MT | J34: 6MT | K34: 7500 | L34: 3600 | M34: =+L34+K34 -> 11100 | O34: =5000*2 -> 10000 | P34: 3600 | Q34: =+P34+O34 -> 13600 | V34: 5000
A35: 9 | B35: 18.04.25 | C35: Gubba-Medchal | D35: Potential-ALEAP | F35: TS06UA7249 | I35: 9MT | J35: 9MT | K35: 8500 | L35: 4800 | M35: =+L35+K35 -> 13300 | O35: =5000*3 -> 15000 | P35: 4800 | Q35: =+P35+O35 -> 19800 | V35: 5000
A36: 7 | B36: 18.04.25 | C36: Gubba-Medchal | D36: Potential-ALEAP | F36: TG08T8450 | I36: 3MT | J36: 3MT | K36: 5000 | L36: 2400 | M36: =+L36+K36 -> 7400 | O36: 5000 | P36: 2400 | Q36: =+P36+O36 -> 7400 | V36: 3000
A37: 8 | B37: 18.04.25 | C37: Priya feeds - Cherlapally | D37: IIL-Karkapatla | F37: TS12UB2595 | I37: 5MT | J37: 6MT | K37: 7500 | L37: 3600 | M37: =+L37+K37 -> 11100 | O37: =5000*2 -> 10000 | P37: 3600 | Q37: =+P37+O37 -> 13600 | V37: 5000
A38: 10 | B38: 18.04.25 | C38: IIL-Karkapatla | D38: IIL-UPPAL | F38: AP20TA1171 | I38: 1MT | J38: 1MT | K38: 3500 | L38: 1200 | M38: =+L38+K38 -> 4700 | O38: 2800 | P38: 1200 | Q38: =+P38+O38 -> 4000 | V38: 3500
A39: 11 | B39: 21.04.25 | C39: Priya feeds - Cherlapally | D39: IIL-Karkapatla | F39: TS06UA7249 | I39: 6MT | J39: 6MT | K39: 7500 | L39: 3600 | M39: =+L39+K39 -> 11100 | O39: =5000*2 -> 10000 | P39: 3600 | Q39: =+P39+O39 -> 13600 | V39: 5000
A40: 12 | B40: 22.04.25 | C40: Gubba-Medchal | D40: Potential-ALEAP | F40: TS06UA7249 | I40: 9MT | J40: 9MT | K40: 8500 | L40: =4*1200 -> 4800 | M40: =+L40+K40 -> 13300 | O40: =5000*3 -> 15000 | P40: =4*1200 -> 4800 | Q40: =+P40+O40 -> 19800 | V40: 5000
...

Sheet May'25
A1: Trip particulars ( 01.05.2025 to 10.05.2025) | P1: Approx
A2: S.No. | B2: Date | C2: From Location | D2: To location | E2: NO OF BOXES | F2: Vehicle No | G2: Gross weight | H2: Volumetric weight | I2: Weight in Tons | J2: Chargeable weight | K2: Rate | L2: Hamali | M2: Total freight | N2: Hamali members | O2: Previous rate | P2: hamali | Q2: Total | R2: Remarks
A3: 1 | B3: 02.05.25 | C3: Priya feeds - Cherlapally | D3: IIL-Karkapatla | F3: TS06UA7249 | H3: 6509 | I3: 6.5MT | J3: 9MT | K3: 8500 | L3: 3600 | M3: =+L3+K3 -> 12100
A4: 2 | B4: 02.05.25 | C4: Priya feeds - Cherlapally | D4: IIL-Karkapatla | F4: TS12UB2595 | H4: 6566 | I4: 6.5MT | J4: 9MT | K4: 8500 | L4: =1200*3 -> 3600 | M4: =+L4+K4 -> 12100
A5: 3 | B5: 05.05.25 | C5: Gubba-Medchal | D5: IIL-Gachibowli | F5: TS12UC3042 | J5: 6MT | K5: 8500 | L5: 3600 | M5: =+L5+K5 -> 12100 | V5: 6000 | W5: 5000
A6: 4 | B6: 05.05.25 | C6: Priya feeds - Cherlapally | D6: IIL-Karkapatla | F6: TS06UA7249 | H6: 6221 | J6: 6MT | K6: 7500 | L6: =1200*3 -> 3600 | M6: =+L6+K6 -> 11100 | V6: 5500 | W6: 5000
A7: 5 | B7: 05.05.25 | C7: Priya feeds - Cherlapally | D7: IIL-Karkapatla | F7: TS12UB2595 | H7: 6300 | J7: 6MT | K7: 7500 | L7: =1200*3 -> 3600 | M7: =+L7+K7 -> 11100 | V7: 5500 | W7: 5000
A8: 6 | B8: 06.05.25 | C8: Priya feeds - Cherlapally | D8: IIL-Karkapatla | F8: TS06UA7249 | H8: 6397 | J8: 6MT | K8: 7500 | L8: 3600 | M8: =+L8+K8 -> 11100 | V8: 3500 | W8: 3500
A9: 9 | B9: 06.05.25 | C9: Priya feeds - Cherlapally | D9: IIL-Karkapatla | F9: TS12UB2595 | H9: 3164 | J9: 3MT | K9: 6000 | L9: 2400 | M9: =+L9+K9 -> 8400 | V9: 3800 | W9: 3000
A10: 7 | B10: 07.05.25 | C10: Priya feeds - Cherlapally | D10: IIL-Karkapatla | F10: TS06UA7249 | H10: 6195 | J10: 6MT | K10: 7500 | L10: 3600 | M10: =+L10+K10 -> 11100 | V10: 4000 | W10: 3000
A11: 8 | B11: 07.05.25 | C11: Priya feeds - Cherlapally | D11: IIL-Karkapatla | F11: TS12UC3042 | H11: 6121 | J11: 6MT | K11: 7500 | L11: 3600 | M11: =+L11+K11 -> 11100 | V11: 4300 | W11: 3500
A12: 10 | B12: 07.05.25 | C12: IIL-Karkapatla | D12: IIL-UPPAL | F12: TS12UB2595 | J12: 6MT | K12: 5900 | L12: 3600 | M12: =+L12+K12 -> 9500 | V12: 5500 | W12: 5000
A13: 11 | B13: 07.05.25 | C13: IIL-Karkapatla | D13: IIL-Gachibowli | F13: TG08T8450 | J13: 1MT | K13: 3500 | L13: 1200 | M13: =+L13+K13 -> 4700 | V13: 5500 | W13: 5000
A14: 12 | B14: 08.05.25 | C14: Priya feeds - Cherlapally | D14: IIL-Karkapatla | F14: TS12UB2595 | H14: 6041 | J14: 6MT | K14: 7500 | L14: 3600 | M14: =+L14+K14 -> 11100 | V14: 2800 | W14: 2500
A15: 13 | B15: 08.05.25 | C15: Priya feeds - Cherlapally | D15: IIL-Karkapatla | F15: TS12UC3042 | H15: 6098 | J15: 6MT | K15: 7500 | L15: 3600 | M15: =+L15+K15 -> 11100 | V15: 5500 | W15: 5000
A16: 14 | B16: 08.05.25 | C16: IIL-Karkapatla | D16: IIL-UPPAL | F16: TS06UA7249 | J16: 6MT | K16: 5900 | L16: 3600 | M16: =+L16+K16 -> 9500 | V16: 5500 | W16: 5000
A17: 15 | B17: 08.05.25 | C17: IIL-Karkapatla | D17: IIL-Gachibowli | F17: TG08T8450 | J17: 1MT | K17: 3500 | L17: 1200 | M17: =+L17+K17 -> 4700 | V17: 5500 | W17: 5000
A18: 16 | B18: 09.05.25 | C18: Gubba-Medchal | D18: Potential-ALEAP | F18: AP29T81940 | J18: 9MT | K18: 8500 | L18: 3600 | M18: =+L18+K18 -> 12100 | V18: 5500 | W18: 5000
A19: 17 | B19: 09.05.25 | C19: Priya feeds - Cherlapally | D19: IIL-Karkapatla | F19: TS12UB2595 | H19: 6089 | J19: 6MT | K19: 7500 | L19: 3600 | M19: =+L19+K19 -> 11100 | V19: 4000 | W19: 3500
A20: 18 | B20: 09.05.25 | C20: Priya feeds - Cherlapally | D20: IIL-Karkapatla | F20: TS06UA7249 | H20: 6107 | J20: 6MT | K20: 7500 | L20: =1200*3 -> 3600 | M20: =+L20+K20 -> 11100 | V20: 5500 | W20: 5000
A21: 19 | B21: 09.05.25 | C21: Priya feeds - Cherlapally | D21: IIL-Karkapatla | F21: AP28TA0092 | H21: 6175 | J21: 6MT | K21: 7500 | L21: 3600 | M21: =+L21+K21 -> 11100 | V21: 5000 | W21: 4500
A22: 20 | B22: 09.05.25 | C22: IIL-Karkapatla | D22: IIL-UPPAL | F22: AP20TA1171 | J22: 2MT | K22: 4900 | L22: 1200 | M22: =+L22+K22 -> 6100 | V22: 3000 | W22: 3000
J23: Total | K23: =SUM(K3:K22) -> 138700 | L23: =SUM(L3:L22) -> 63600 | M23: =SUM(M3:M22) -> 202300 | O23: =SUM(O3:O22) -> 0 | P23: =SUM(P3:P22) -> 0 | Q23: =SUM(Q3:Q22) -> 0 | V23: =SUM(V3:V22) -> 85900 | W23: =SUM(W5:W22) -> 76500
Q24: =Q23-M23 -> -202300
A27: Trip particulars (11.05.2025 to 20.05.2025)
A28: S.No. | B28: Date | C28: From Location | D28: To location | E28: NO OF BOXES | F28: Vehicle No | G28: Gross weight | H28: Volumetric weight | I28: Weight in Tons | J28: Chargeable weight | K28: Rate | L28: Hamali | M28: Total freight
A29: 1 | B29: 12.05.25 | C29: IIL-Uppal | D29: IIL-Karkapatla | F29: TG08T8450 | H29: 6509 | I29: 6.5MT | J29: 2MT | K29: 4500 | L29: 1200 | M29: =+L29+K29 -> 5700
A30: 2 | B30: 12.05.25 | C30: Priya feeds - Cherlapally | D30: IIL-Karkapatla | F30: TS06UA7249 | H30: 6075 | I30: 6.5MT | J30: 6MT | K30: 7500 | L30: =1200*3 -> 3600 | M30: =+L30+K30 -> 11100
A31: 3 | B31: 12.05.25 | C31: Priya feeds - Cherlapally | D31: IIL-Karkapatla | F31: TS05UA0781 | H31: 6085 | J31: 6MT | K31: 7500 | L31: 3600 | M31: =+L31+K31 -> 11100
A32: 4 | B32: 12.05.25 | C32: Potential-ALEAP | D32: IIL-Karkapatla | F32: TS12UB2595 | H32: 3300 | J32: 3MT | K32: 5200 | L32: 2400 | M32: =+L32+K32 -> 7600
A33: 5 | B33: 12.05.25 | C33: IIL-Karkapatla | D33: IIL-Gachibowli | F33: TG08T8450 | J33: 2MT | K33: 5000 | L33: 1200 | M33: =+L33+K33 -> 6200
A34: 6 | B34: 13.05.25 | C34: Priya feeds - Cherlapally | D34: IIL-Karkapatla | F34: TS06UA7249 | H34: 6175 | J34: 6MT | K34: 7500 | L34: 3600 | M34: =+L34+K34 -> 11100
A35: 7 | B35: 13.05.25 | C35: Priya feeds - Cherlapally | D35: IIL-Karkapatla | F35: TS12UB2595 | H35: 6046 | J35: 6MT | K35: 7500 | L35: 3600 | M35: =+L35+K35 -> 11100
A36: 8 | B36: 13.05.25 | C36: Priya feeds - Cherlapally | D36: IIL-Karkapatla | F36: TS05UA0781 | H36: 6104 | J36: 6MT | K36: 7500 | L36: 3600 | M36: =+L36+K36 -> 11100
A37: 9 | B37: 13.05.25 | C37: IIL-Uppal | D37: IIL-Gachibowli | F37: AP20TA1171 | J37: 1MT | K37: 2800 | L37: 600 | M37: =+L37+K37 -> 3400
A38: 10 | B38: 13.05.25 | C38: IIL-Karkapatla | D38: IIL-Uppal | F38: AP20TA1171 | J38: 1MT | K38: 3500 | L38: 600 | M38: =+L38+K38 -> 4100
A39: 11 | B39: 14.05.25 | C39: Gubba-Medchal | D39: Potential-ALEAP | F39: TS05UA0781 | H39: 9122 | J39: 9MT | K39: 8500 | L39: 4800 | M39: =+L39+K39 -> 13300
A40: 12 | B40: 15.05.25 | C40: Priya feeds - Cherlapally | D40: IIL-Karkapatla | F40: TS12UB2595 | H40: 6228 | J40: 6MT | K40: 7500 | L40: 3600 | M40: =+L40+K40 -> 11100
A41: 13 | B41: 16.05.25 | C41: IIL-Gachibowli | D41: IIL-Karkapatla | F41: TG08T8450 | J41: 2MT | K41: 5600 | L41: 1200 | M41: =+L41+K41 -> 6800
A42: 14 | B42: 16.05.25 | C42: Priya feeds - Cherlapally | D42: IIL-Karkapatla | F42: TS12UB2595 | H42: 6028 | J42: 6MT | K42: 7500 | L42: 3600 | M42: =+L42+K42 -> 11100
...

Sheet June'25
A1: Trip particulars ( 01.06.2025 to 14.06.2025) | P1: Approx
A2: S.No. | B2: Date | C2: From Location | D2: To location | E2: NO OF BOXES | F2: Vehicle No | G2: Gross weight | H2: Volumetric weight | I2: Weight in Tons | J2: Chargeable weight | K2: Rate | L2: Hamali | M2: Total freight | N2: Hamali members | O2: Previous rate | P2: hamali | Q2: Total | R2: Remarks
A3: 1 | B3: 02.06.25 | C3: Priya feeds - Cherlapally | D3: IIL-Karkapatla | F3: TS12UB2595 | H3: 6509 | I3: 6.5MT | J3: 6MT | K3: 7500 | L3: 3600 | M3: =+L3+K3 -> 11100
A4: 2 | B4: 02.06.25 | C4: Priya feeds - Cherlapally | D4: IIL-Karkapatla | F4: TS12UC3042 | H4: 6566 | I4: 6.5MT | J4: 6MT | K4: 7500 | L4: =1200*3 -> 3600 | M4: =+L4+K4 -> 11100
A5: 3 | B5: 02.06.25 | C5: Priya feeds - Cherlapally | D5: IIL-Karkapatla | F5: TS05UA0781 | J5: 6MT | K5: 7500 | L5: 3600 | M5: =+L5+K5 -> 11100 | V5: 6000 | W5: 5000
A6: 4 | B6: 02.06.25 | C6: Gubba-Medchal | D6: Potential-ALEAP | F6: TS06UA7249 | H6: 6221 | J6: 9MT | K6: 8500 | L6: 4800 | M6: =+L6+K6 -> 13300 | V6: 5500 | W6: 5000
A7: 5 | B7: 02.06.25 | C7: Gubba-Medchal | D7: Potential-ALEAP | F7: TS08UE8153 | H7: 3164 | J7: 3MT | K7: 5000 | L7: 2400 | M7: =+L7+K7 -> 7400 | V7: 5500 | W7: 5000
A8: 6 | B8: 03.06.25 | C8: Priya feeds - Cherlapally | D8: IIL-Karkapatla | F8: TS12UB2595 | H8: 6397 | J8: 6MT | K8: 7500 | L8: 3600 | M8: =+L8+K8 -> 11100 | V8: 3500 | W8: 3500
A9: 7 | B9: 04.06.25 | C9: Priya feeds - Cherlapally | D9: IIL-Karkapatla | F9: TS12UB2595 | H9: 3164 | J9: 6MT | K9: 7500 | L9: 3600 | M9: =+L9+K9 -> 11100 | V9: 3800 | W9: 3000
A10: 8 | B10: 04.06.25 | C10: Bollaram | D10: IIL-Karkapatla | F10: TS06UA7249 | H10: 6195 | J10: 3MT | K10: 5200 | L10: 2400 | M10: =+L10+K10 -> 7600 | S10: CONSIDERED ALEAP TO KKP | V10: 4000 | W10: 3000
A11: 9 | B11: 05.06.25 | C11: Priya feeds - Cherlapally | D11: IIL-Karkapatla | F11: TS06UA7249 | H11: 6121 | J11: 6MT | K11: 7500 | L11: 3600 | M11: =+L11+K11 -> 11100 | V11: 4300 | W11: 3500
A12: 10 | B12: 05.06.25 | C12: Priya feeds - Cherlapally | D12: IIL-Karkapatla | F12: TS12UC3042 | J12: 6MT | K12: 7500 | L12: 3600 | M12: =+L12+K12 -> 11100 | V12: 5500 | W12: 5000
A13: 11 | B13: 05.06.25 | C13: IIL-Karkapatla | D13: IIL-UPPAL | F13: TS12UB2595 | J13: 6MT | K13: 5900 | L13: 2400 | M13: =+L13+K13 -> 8300 | V13: 5500 | W13: 5000
A14: 12 | B14: 06.06.25 | C14: Priya feeds - Cherlapally | D14: IIL-Karkapatla | F14: TS06UA7249 | H14: 6041 | J14: 6MT | K14: 7500 | L14: 3600 | M14: =+L14+K14 -> 11100 | V14: 2800 | W14: 2500
A15: 13 | B15: 06.06.25 | C15: IIL-Karkapatla | D15: IIL-UPPAL | F15: TS12UB2595 | H15: 6098 | J15: 6MT | K15: 5900 | L15: 3600 | M15: =+L15+K15 -> 9500 | V15: 5500 | W15: 5000
A16: 14 | B16: 06.06.25 | C16: IIL-Karkapatla | D16: IIL-UPPAL | F16: TS06UA7249 | J16: 6MT | K16: 5900 | L16: 3600 | M16: =+L16+K16 -> 9500 | V16: 5500 | W16: 5000
A17: 15 | B17: 09.06.25 | C17: IIL-Karkapatla | D17: IIL-UPPAL | F17: TS12UB2595 | J17: 6MT | K17: 5900 | L17: 3600 | M17: =+L17+K17 -> 9500 | V17: 5500 | W17: 5000
A18: 16 | B18: 09.06.25 | C18: IIL-Karkapatla | D18: IIL-UPPAL | F18: TS12UC3042 | J18: 6MT | K18: 5900 | L18: 3600 | M18: =+L18+K18 -> 9500 | V18: 5500 | W18: 5000
A19: 17 | B19: 09.06.25 | C19: Priya feeds - Cherlapally | D19: IIL-Karkapatla | F19: TS12UB2595 | H19: 6089 | J19: 6MT | K19: 7500 | L19: 3600 | M19: =+L19+K19 -> 11100 | V19: 4000 | W19: 3500
A20: 18 | B20: 10.06.25 | C20: Priya feeds - Cherlapally | D20: IIL-Karkapatla | F20: TS06UA7249 | H20: 6107 | J20: 6MT | K20: 7500 | L20: =1200*3 -> 3600 | M20: =+L20+K20 -> 11100 | V20: 5500 | W20: 5000
A21: 19 | B21: 10.06.25 | C21: Gubba-Medchal | D21: Potential-ALEAP | F21: TS06UA7249 | H21: 6175 | J21: 9MT | K21: 8500 | L21: 4800 | M21: =+L21+K21 -> 13300 | V21: 5000 | W21: 4500
A22: 20 | B22: 10.06.25 | C22: Gubba-Medchal | D22: Potential-ALEAP | F22: TS05UA0781 | J22: 9MT | K22: 8500 | L22: 4800 | M22: =+L22+K22 -> 13300
A23: 21 | B23: 10.06.25 | C23: IIL-Karkapatla | D23: IIL-UPPAL | F23: AP20TA1171 | J23: 1MT | K23: 3500 | L23: 1200 | M23: =+L23+K23 -> 4700
A24: 22 | B24: 10.06.25 | C24: IIL-Karkapatla | D24: IIL-Gachibowli | F24: TG08T8450 | J24: 1MT | K24: 3500 | L24: 1200 | M24: =+L24+K24 -> 4700
A25: 23 | B25: 12.06.25 | C25: IIL-Karkapatla | D25: IIL-UPPAL | F25: TS12UB2595 | J25: 6MT | K25: 5900 | L25: 3600 | M25: =+L25+K25 -> 9500
A26: 24 | B26: 13.06.25 | C26: IIL-Karkapatla | D26: RGAI-shamshabad | F26: AP20TA1171 | J26: 1MT | K26: 5500 | L26: 1200 | M26: =+L26+K26 -> 6700
A27: 25 | B27: 13.06.25 | C27: IIL-Karkapatla | D27: IIL-UPPAL | F27: TG08T8450 | J27: 2MT | K27: 4900 | L27: 1200 | M27: =+L27+K27 -> 6100
A28: 26 | B28: 13.06.25 | C28: Potential-ALEAP | D28: IIL-Karkapatla | F28: TS05UA0781 | J28: 6MT | K28: 7500 | L28: 3600 | M28: =+L28+K28 -> 11100
A29: 27 | B29: 13.06.25 | C29: Priya feeds - Cherlapally | D29: IIL-Karkapatla | F29: TS12UB2595 | J29: 6MT | K29: 7500 | L29: 3600 | M29: =+L29+K29 -> 11100
A30: 28 | B30: 13.06.25 | C30: Gubba-Medchal | D30: Potential-ALEAP | F30: TS06UA7249 | J30: 9MT | K30: 8500 | L30: 4800 | M30: =+L30+K30 -> 13300
A31: 29 | B31: 14.06.25 | C31: IIL-Gachibowli | D31: IIL-Karkapatla | F31: TS12UB2595 | J31: 3MT | K31: 5600 | L31: 1200 | M31: =+L31+K31 -> 6800 | V31: 3000 | W31: 3000
J32: Total | K32: =SUM(K3:K31) -> 192600 | L32: =SUM(L3:L31) -> 93600 | M32: =SUM(M3:M31) -> 286200 | O32: =SUM(O3:O31) -> 0 | P32: =SUM(P3:P31) -> 0 | Q32: =SUM(Q3:Q31) -> 0 | V32: =SUM(V3:V31) -> 85900 | W32: =SUM(W5:W31) -> 76500
Q33: =Q32-M32 -> -286200
A35: Trip particulars ( 15.06.2025 to 30.06.2025)
A36: S.No. | B36: Date | C36: From Location | D36: To location | E36: NO OF BOXES | F36: Vehicle No | G36: Gross weight | H36: Volumetric weight | I36: Weight in Tons | J36: Chargeable weight | K36: Rate | L36: Hamali | M36: Total freight
A37: 1 | B37: 16.06.25 | C37: Priya feeds - Cherlapally | D37: IIL-Karkapatla | F37: TS06UA7249 | H37: 6509 | I37: 6.5MT | J37: 6MT | K37: 7500 | L37: 3600 | M37: =+L37+K37 -> 11100
A38: 2 | B38: 16.06.25 | C38: Priya feeds - Cherlapally | D38: IIL-Karkapatla | F38: TS12UB2595 | H38: 6566 | I38: 6.5MT | J38: 6MT | K38: 7500 | L38: =1200*3 -> 3600 | M38: =+L38+K38 -> 11100
A39: 3 | B39: 16.06.25 | C39: Priya feeds - Cherlapally | D39: IIL-Karkapatla | F39: TS05UA0781 | J39: 6MT | K39: 7500 | L39: 3600 | M39: =+L39+K39 -> 11100
A40: 4 | B40: 17.06.25 | C40: Priya feeds - Cherlapally | D40: IIL-Karkapatla | F40: TS12UB2595 | H40: 6221 | J40: 6MT | K40: 7500 | L40: 3600 | M40: =+L40+K40 -> 11100
A41: 5 | B41: 18.06.25 | C41: Gubba-Medchal | D41: Potential-ALEAP | F41: TS06UA7249 | H41: 3164 | J41: 6MT | K41: 7500 | L41: 3600 | M41: =+L41+K41 -> 11100
...

Sheet July'25
A1: Trip particulars ( 01.07.2025 to 15.07.2025)
A2: S.No. | B2: Date | C2: From Location | D2: To location | E2: Vehicle No | F2: Chargeable weight | G2: Rate | H2: Hamali | I2: Total freight
A3: 1 | B3: 01.07.25 | C3: Potential-ALEAP | D3: IIL-Karkapatla | E3: TS12UB2595 | F3: 6MT | G3: 7500 | H3: 3600 | I3: =+H3+G3 -> 11100
A4: 2 | B4: 01.07.25 | C4: IIL-Karkapatla | D4: IIL-Gachibowli | E4: TG08T8450 | F4: 3MT | G4: 5000 | H4: 1200 | I4: =+H4+G4 -> 6200
A5: 3 | B5: 02.07.25 | C5: Priya feeds - Cherlapally | D5: IIL-Karkapatla | E5: TS12UB2595 | F5: 6MT | G5: 7500 | H5: 3600 | I5: =+H5+G5 -> 11100
A6: 4 | B6: 02.07.25 | C6: IIL-Karkapatla | D6: IIL-Gachibowli | E6: TG08T8450 | F6: 3MT | G6: 5000 | H6: 1200 | I6: =+H6+G6 -> 6200
A7: 5 | B7: 04.07.25 | C7: Potential-ALEAP | D7: IIL-Karkapatla | E7: TS12UB2595 | F7: 6MT | G7: 7500 | H7: 3600 | I7: =+H7+G7 -> 11100
A8: 6 | B8: 04.07.25 | C8: Priya feeds - Cherlapally | D8: IIL-Karkapatla | E8: TS12UC3042 | F8: 6MT | G8: 7500 | H8: 3600 | I8: =+H8+G8 -> 11100
A9: 7 | B9: 04.07.25 | C9: IIL-Karkapatla | D9: IIL-UPPAL | E9: TS06UA7249 | F9: 6MT | G9: 5900 | H9: 3600 | I9: =+H9+G9 -> 9500
A10: 8 | B10: 04.07.25 | C10: IIL-Karkapatla | D10: IIL-Gachibowli | E10: TG08T8450 | F10: 3MT | G10: 5000 | H10: 1200 | I10: =+H10+G10 -> 6200
A11: 9 | B11: 07.07.25 | C11: Priya feeds - Cherlapally | D11: IIL-Karkapatla | E11: TS06UA7249 | F11: 6MT | G11: 7500 | H11: 3600 | I11: =+H11+G11 -> 11100
A12: 10 | B12: 07.07.25 | C12: Priya feeds - Cherlapally | D12: IIL-Karkapatla | E12: TS12UC3042 | F12: 6MT | G12: 7500 | H12: 3600 | I12: =+H12+G12 -> 11100
A13: 11 | B13: 07.07.25 | C13: Priya feeds - Cherlapally | D13: IIL-Karkapatla | E13: TS05UA0781 | F13: 6MT | G13: 7500 | H13: 3600 | I13: =+H13+G13 -> 11100
A14: 12 | B14: 07.07.25 | C14: Potential-ALEAP | D14: IIL-Karkapatla | E14: TS12UB2595 | F14: 6MT | G14: 7500 | H14: 3600 | I14: =+H14+G14 -> 11100
... A19: 17 | B19: 08.07.25 | C19: Gubba-Medchal | D19: Potential-ALEAP | E19: AP15TC5064 | F19: 6MT | G19: 8500 | H19: 3600 | I19: =+H19+G19 -> 12100
A20: 18 | B20: 08.07.25 | C20: IIL-Karkapatla | D20: IIL-UPPAL | E20: TS12UB2595 | F20: 6MT | G20: 5900 | H20: =1200*3 -> 3600 | I20: =+H20+G20 -> 9500
A21: 19 | B21: 09.07.25 | C21: Priya feeds - Cherlapally | D21: IIL-Karkapatla | E21: TS12UB2595 | F21: 6MT | G21: 7500 | H21: 3600 | I21: =+H21+G21 -> 11100
A22: 20 | B22: 09.07.25 | C22: Priya feeds - Cherlapally | D22: IIL-Karkapatla | E22: TS05UA0781 | F22: 6MT | G22: 7500 | H22: 3600 | I22: =+H22+G22 -> 11100
A23: 21 | B23: 09.07.25 | C23: Potential-ALEAP | D23: IIL-Karkapatla | E23: TS06UA7249 | F23: 6MT | G23: 7500 | H23: 3600 | I23: =+H23+G23 -> 11100
A24: 22 | B24: 09.07.25 | C24: Potential-ALEAP | D24: IIL-Karkapatla | E24: TS12UC3042 | F24: 6MT | G24: 7500 | H24: 3600 | I24: =+H24+G24 -> 11100
A25: 23 | B25: 10.07.25 | C25: Priya feeds - Cherlapally | D25: IIL-Karkapatla | E25: TS12UB2595 | F25: 6MT | G25: 7500 | H25: 3600 | I25: =+H25+G25 -> 11100
A26: 24 | B26: 11.07.25 | C26: Priya feeds - Cherlapally | D26: IIL-Karkapatla | E26: TS12UB2595 | F26: 6MT | G26: 7500 | H26: 3600 | I26: =+H26+G26 -> 11100
A27: 25 | B27: 11.07.25 | C27: Potential-ALEAP | D27: IIL-Karkapatla | E27: TS12UC3042 | F27: 6MT | G27: 7500 | H27: 3600 | I27: =+H27+G27 -> 11100
A28: 26 | B28: 11.07.25 | C28: Gubba-Medchal | D28: Potential-ALEAP | E28: TS06UA7249 | F28: 6MT | G28: 8500 | H28: 3600 | I28: =+H28+G28 -> 12100
A29: 27 | B29: 11.07.25 | C29: Gubba-Medchal | D29: Potential-ALEAP | E29: TS05UA0781 | F29: 6MT | G29: 8500 | H29: 3600 | I29: =+H29+G29 -> 12100
A30: 28 | B30: 14.07.25 | C30: Potential-ALEAP | D30: IIL-Karkapatla | E30: TS12UB2595 | F30: 6MT | G30: 7500 | H30: 3600 | I30: =+H30+G30 -> 11100
A31: 29 | B31: 14.07.25 | C31: Potential-ALEAP | D31: IIL-Karkapatla | E31: TS06UA7249 | F31: 6MT | G31: 7500 | H31: 3600 | I31: =+H31+G31 -> 11100
A32: 30 | B32: 15.07.25 | C32: Priya feeds - Cherlapally | D32: IIL-Karkapatla | E32: TS12UB2595 | F32: 6MT | G32: 7500 | H32: 3600 | I32: =+H32+G32 -> 11100
... A34: 32 | B34: 15.07.25 | C34: Gubba-Medchal | D34: Potential-ALEAP | E34: TS06UA7249 | F34: 6MT | G34: 8500 | H34: 3600 | I34: =+H34+G34 -> 12100
F35: Total | G35: =SUM(G3:G34) -> 231800 | H35: =SUM(H3:H34) -> 105600 | I35: =SUM(I3:I34) -> 337400
A38: Trip particulars ( 16.07.2025 to 31.07.2025)
A39: S.No. | B39: Date | C39: From Location | D39: To location | E39: Vehicle No | F39: Chargeable weight | G39: Rate | H39: Hamali | I39: Total freight
A40: 1 | B40: 16.07.25 | C40: Priya feeds - Cherlapally | D40: IIL-Karkapatla | E40: TS12UC3042 | F40: 6MT | G40: 7500 | H40: 3600 | I40: =+H40+G40 -> 11100
A41: 2 | B41: 16.07.25 | C41: Priya feeds - Cherlapally | D41: IIL-Karkapatla | E41: TS05UA0781 | F41: 6MT | G41: 7500 | H41: 3600 | I41: =+H41+G41 -> 11100
A42: 3 | B42: 16.07.25 | C42: Potential-ALEAP | D42: IIL-Karkapatla | E42: AP28TA0092 | F42: 6MT | G42: 7500 | H42: 3600 | I42: =+H42+G42 -> 11100
A43: 4 | B43: 16.07.25 | C43: Gubba-Medchal | D43: Potential-ALEAP | E43: TS06UA7249 | F43: 6MT | G43: 8500 | H43: 3600 | I43: =+H43+G43 -> 12100
A44: 5 | B44: 16.07.25 | C44: IIL-Karkapatla | D44: IIL-UPPAL | E44: TS12UB2595 | F44: 6MT | G44: 5900 | H44: 3600 | I44: =+H44+G44 -> 9500
A45: 6 | B45: 17.07.25 | C45: Priya feeds - Cherlapally | D45: IIL-Karkapatla | E45: TS12UB2595 | F45: 6MT | G45: 7500 | H45: 3600 | I45: =+H45+G45 -> 11100
A46: 7 | B46: 17.07.25 | C46: Potential-ALEAP | D46: IIL-Karkapatla | E46: AP28TA0092 | F46: 6MT | G46: 7500 | H46: 3600 | I46: =+H46+G46 -> 11100
A47: 8 | B47: 17.07.25 | C47: Gubba-Medchal | D47: Potential-ALEAP | E47: TS06UA7249 | F47: 6MT | G47: 8500 | H47: 3600 | I47: =+H47+G47 -> 12100
...

Sheet Aug'25
A1: Trip particulars ( 01.08.2025 to 15.08.2025)
A2: S.No. | B2: Date | C2: From Location | D2: To location | E2: Vehicle No | F2: Chargeable weight | G2: Rate | H2: Hamali | I2: Total freight
A3: 1 | B3: 01.08.25 | C3: Potential-ALEAP | D3: IIL-Karkapatla | E3: TS15UA2555 | F3: 6MT | G3: 7500 | H3: 3600 | I3: =+H3+G3 -> 11100
A4: 2 | B4: 01.08.25 | C4: Gubba-Medchal | D4: Potential-ALEAP | E4: TS06UA7249 | F4: 6MT | G4: 8500 | H4: 3600 | I4: =+H4+G4 -> 12100
A5: 3 | B5: 01.08.25 | C5: Gubba-Medchal | D5: Potential-ALEAP | E5: TS12UB2595 | F5: 6MT | G5: 8500 | H5: 3600 | I5: =+H5+G5 -> 12100
A6: 4 | B6: 01.08.25 | C6: Gubba-Medchal | D6: Potential-ALEAP | E6: TS12UC3042 | F6: 6MT | G6: 8500 | H6: 3600 | I6: =+H6+G6 -> 12100
A7: 5 | B7: 02.08.25 | C7: Gubba-Medchal | D7: Potential-ALEAP | E7: TS12UB2595 | F7: 6MT | G7: 8500 | H7: 3600 | I7: =+H7+G7 -> 12100
A8: 6 | B8: 02.08.25 | C8: Gubba-Medchal | D8: Potential-ALEAP | E8: TS06UA7249 | F8: 6MT | G8: 8500 | H8: 3600 | I8: =+H8+G8 -> 12100
A9: 7 | B9: 04.08.25 | C9: Potential-ALEAP | D9: IIL-Karkapatla | E9: TS12UB2595 | F9: 6MT | G9: 7500 | H9: 3600 | I9: =+H9+G9 -> 11100
A10: 8 | B10: 05.08.25 | C10: Gubba-Medchal | D10: Potential-ALEAP | E10: TS06UA7249 | F10: 6MT | G10: 8500 | H10: 3600 | I10: =+H10+G10 -> 12100
A11: 9 | B11: 05.08.25 | C11: Gubba-Medchal | D11: Potential-ALEAP | E11: TS12UB2595 | F11: 6MT | G11: 8500 | H11: 3600 | I11: =+H11+G11 -> 12100
A12: 10 | B12: 05.08.25 | C12: IIL-Karkapatla | D12: IIL-UPPAL | E12: TS12UC3042 | F12: 6MT | G12: 5900 | H12: 3600 | I12: =+H12+G12 -> 9500
A13: 11 | B13: 06.08.25 | C13: Potential-ALEAP | D13: IIL-Karkapatla | E13: TS12UB2595 | F13: 6MT | G13: 7500 | H13: 3600 | I13: =+H13+G13 -> 11100
A14: 12 | B14: 06.08.25 | C14: Gubba-Medchal | D14: Potential-ALEAP | E14: TS06UA7249 | F14: 6MT | G14: 8500 | H14: 3600 | I14: =+H14+G14 -> 12100
... A19: 17 | B19: 08.08.25 | C19: Priya feeds - Cherlapally | D19: IIL-Karkapatla | E19: TS12UC3042 | F19: 6MT | G19: 7500 | H19: 3600 | I19: =+H19+G19 -> 11100
A20: 18 | B20: 08.08.25 | C20: Potential-ALEAP | D20: IIL-Karkapatla | E20: AP28TE0092 | F20: 6MT | G20: 7500 | H20: =1200*3 -> 3600 | I20: =+H20+G20 -> 11100
A21: 19 | B21: 08.08.25 | C21: Potential-ALEAP | D21: IIL-Karkapatla | E21: TG13T2292 | F21: 6MT | G21: 7500 | H21: 3600 | I21: =+H21+G21 -> 11100
A22: 20 | B22: 11.08.25 | C22: Priya feeds - Cherlapally | D22: IIL-Karkapatla | E22: TS06UA7249 | F22: 6MT | G22: 7500 | H22: 3600 | I22: =+H22+G22 -> 11100
A23: 21 | B23: 11.08.25 | C23: Priya feeds - Cherlapally | D23: IIL-Karkapatla | E23: TS12UB2595 | F23: 6MT | G23: 7500 | H23: 3600 | I23: =+H23+G23 -> 11100
A24: 22 | B24: 11.08.25 | C24: IIL-Karkapatla | D24: IIL-Gachibowli | E24: AP20TA1171 | F24: 1MT | G24: 3500 | H24: 600 | I24: =+H24+G24 -> 4100
A25: 23 | B25: 12.08.25 | C25: Priya feeds - Cherlapally | D25: IIL-Karkapatla | E25: TS12UB2595 | F25: 6MT | G25: 7500 | H25: 3600 | I25: =+H25+G25 -> 11100
A26: 24 | B26: 12.08.25 | C26: Priya feeds - Cherlapally | D26: IIL-Karkapatla | E26: TS06UA7249 | F26: 6MT | G26: 7500 | H26: 3600 | I26: =+H26+G26 -> 11100
A27: 25 | B27: 12.08.25 | C27: IIL-Karkapatla | D27: IIL-UPPAL | E27: TG08T8450 | F27: 1MT | G27: 3500 | H27: 600 | I27: =+H27+G27 -> 4100
A28: 26 | B28: 13.08.25 | C28: Priya feeds - Cherlapally | D28: IIL-Karkapatla | E28: TS12UB2595 | F28: 6MT | G28: 7500 | H28: 3600 | I28: =+H28+G28 -> 11100
A29: 27 | B29: 13.08.25 | C29: Priya feeds - Cherlapally | D29: IIL-Karkapatla | E29: TS12UC3042 | F29: 6MT | G29: 7500 | H29: 3600 | I29: =+H29+G29 -> 11100
A30: 28 | B30: 13.08.25 | C30: Potential-ALEAP | D30: IIL-Karkapatla | E30: TS06UA7249 | F30: 6MT | G30: 7500 | H30: 3600 | I30: =+H30+G30 -> 11100
A31: 29 | B31: 14.08.25 | C31: Priya feeds - Cherlapally | D31: IIL-Karkapatla | E31: TS12UB2595 | F31: 6MT | G31: 7500 | H31: 3600 | I31: =+H31+G31 -> 11100
A32: 30 | B32: 14.08.25 | C32: Priya feeds - Cherlapally | D32: IIL-Karkapatla | E32: TS12UC3042 | F32: 6MT | G32: 7500 | H32: 3600 | I32: =+H32+G32 -> 11100
... A36: 34 | B36: 14.08.25 | C36: IIL-Karkapatla | D36: IIL-UPPAL | E36: AP20TA1171 | F36: 1MT | G36: 2800 | H36: 800 | I36: =+H36+G36 -> 3600
F37: Total | G37: =SUM(G3:G36) -> 251700 | H37: =SUM(H3:H36) -> 113600 | I37: =SUM(I3:I36) -> 365300
A41: Trip particulars ( 16.08.2025 to 31.08.2025)
A42: S.No. | B42: Date | C42: From Location | D42: To location | E42: Vehicle No | F42: Chargeable weight | G42: Rate | H42: Hamali | I42: Total freight
A43: 1 | B43: 18.08.25 | C43: Priya feeds - Cherlapally | D43: IIL-Karkapatla | E43: TS06UA7249 | F43: 6MT | G43: 7500 | H43: 3600 | I43: =+H43+G43 -> 11100
A44: 2 | B44: 18.08.25 | C44: Priya feeds - Cherlapally | D44: IIL-Karkapatla | E44: TS12UB2595 | F44: 6MT | G44: 7500 | H44: 3600 | I44: =+H44+G44 -> 11100
A45: 3 | B45: 18.08.25 | C45: Priya feeds - Cherlapally | D45: IIL-Karkapatla | E45: TS05UA0781 | F45: 6MT | G45: 7500 | H45: 3600 | I45: =+H45+G45 -> 11100
A46: 4 | B46: 18.08.25 | C46: Potential-ALEAP | D46: IIL-Karkapatla | E46: AP28TE0092 | F46: 6MT | G46: 7500 | H46: 3600 | I46: =+H46+G46 -> 11100
A47: 5 | B47: 18.08.25 | C47: Potential-ALEAP | D47: IIL-Karkapatla | E47: TS15UA2555 | F47: 6MT | G47: 7500 | H47: 3600 | I47: =+H47+G47 -> 11100
A48: 6 | B48: 18.08.25 | C48: Potential-ALEAP | D48: IIL-Karkapatla | E48: TS12UC3042 | F48: 6MT | G48: 7500 | H48: 3600 | I48: =+H48+G48 -> 11100
A49: 7 | B49: 18.08.25 | C49: IIL-Karkapatla | D49: IIL-UPPAL | E49: TG08T8450 | F49: 3MT | G49: 4900 | H49: 1200 | I49: =+H49+G49 -> 6100
A50: 8 | B50: 19.08.25 | C50: Priya feeds - Cherlapally | D50: IIL-Karkapatla | E50: TS06UA7249 | F50: 6MT | G50: 7500 | H50: 3600 | I50: =+H50+G50 -> 11100
...

Sheet Sept'25
A1: Trip particulars ( 01.09.2025 to 15.09.2025)
A2: S.No. | B2: Date | C2: From Location | D2: To location | E2: Vehicle No | F2: Chargeable weight | G2: Rate | H2: Hamali | I2: Total freight
A3: 1 | B3: 01.09.25 | C3: Priya feeds - Cherlapally | D3: IIL-Karkapatla | E3: TS12UB2595 | F3: 6MT | G3: 7500 | H3: 3600 | I3: =+H3+G3 -> 11100
A4: 2 | B4: 01.09.25 | C4: Priya feeds - Cherlapally | D4: IIL-Karkapatla | E4: TG12T6078 | F4: 6MT | G4: 7500 | H4: 3600 | I4: =+H4+G4 -> 11100
A5: 3 | B5: 01.09.25 | C5: Potential-ALEAP | D5: IIL-Karkapatla | E5: TS05UA0781 | F5: 6MT | G5: 7500 | H5: 3600 | I5: =+H5+G5 -> 11100
A6: 4 | B6: 01.09.25 | C6: Potential-ALEAP | D6: IIL-Karkapatla | E6: TS12VC3024 | F6: 6MT | G6: 7500 | H6: 3600 | I6: =+H6+G6 -> 11100
A7: 5 | B7: 02.09.25 | C7: Priya feeds - Cherlapally | D7: IIL-Karkapatla | E7: TS12UB2595 | F7: 6MT | G7: 7500 | H7: 3600 | I7: =+H7+G7 -> 11100
A8: 6 | B8: 02.09.25 | C8: Potential-ALEAP | D8: IIL-Karkapatla | E8: TS05UA0781 | F8: 6MT | G8: 7500 | H8: 3600 | I8: =+H8+G8 -> 11100
A9: 7 | B9: 02.09.25 | C9: Sanzyem | D9: IIL-Karkapatla | E9: TS12VC3024 | F9: 6MT | G9: 6200 | H9: 3600 | I9: =+H9+G9 -> 9800 | J9: considered KKP to GCH
A10: 8 | B10: 02.09.25 | C10: Sanzyem | D10: IIL-Karkapatla | E10: TG12T6078 | F10: 6MT | G10: 6200 | H10: 3600 | I10: =+H10+G10 -> 9800 | J10: considered KKP to GCH
A11: 9 | B11: 02.09.25 | C11: Turkapally | D11: IIL-Karkapatla | E11: AP20TA1171 | F11: 1MT | G11: 3500 | H11: 600 | I11: =+H11+G11 -> 4100
A12: 10 | B12: 03.09.25 | C12: Potential-ALEAP | D12: IIL-Karkapatla | E12: TS12UB2595 | F12: 6MT | G12: 7500 | H12: 3600 | I12: =+H12+G12 -> 11100
A13: 11 | B13: 03.09.25 | C13: IIL-Karkapatla | D13: IIL-Gachhibowli | E13: AP20TA1171 | F13: 1MT | G13: 3500 | H13: 600 | I13: =+H13+G13 -> 4100
A14: 12 | B14: 04.09.25 | C14: Priya feeds - Cherlapally | D14: IIL-Karkapatla | E14: TG12T6078 | F14: 6MT | G14: 7500 | H14: 3600 | I14: =+H14+G14 -> 11100
A15: 13 | B15: 04.09.25 | C15: Potential-ALEAP | D15: IIL-Karkapatla | E15: TS06UA7249 | F15: 6MT | G15: 7500 | H15: 3600 | I15: =+H15+G15 -> 11100
A16: 14 | B16: 04.09.25 | C16: IIL-Karkapatla | D16: IIL-Uppal | E16: TS05UA0781 | F16: 6MT | G16: 5900 | H16: 3600 | I16: =+H16+G16 -> 9500
A17: 15 | B17: 04.09.25 | C17: Gubba-Medchal | D17: IIL-Gachhibowli | E17: TS12 VC3024 | F17: 6MT | G17: 8500 | H17: 3600 | I17: =+H17+G17 -> 12100
A18: 16 | B18: 04.09.25 | C18: Gubba-Medchal | D18: IIL-Gachhibowli | E18: TS12VB2595 | F18: 6MT | G18: 8500 | H18: 3600 | I18: =+H18+G18 -> 12100
A19: 17 | B19: 05.09.25 | C19: IIL-Karkapatla | D19: IIL-Gachhibowli | E19: TG12T6078 | F19: 6MT | G19: 6200 | H19: 3600 | I19: =+H19+G19 -> 9800
A20: 18 | B20: 05.09.25 | C20: Priya feeds - Cherlapally | D20: IIL-Karkapatla | E20: TS06UA7249 | F20: 6MT | G20: 7500 | H20: 3600 | I20: =+H20+G20 -> 11100
A21: 19 | B21: 05.09.25 | C21: Potential-ALEAP | D21: IIL-Karkapatla | E21: TS12UB2595 | F21: 6MT | G21: 7500 | H21: 3600 | I21: =+H21+G21 -> 11100
A22: 20 | B22: 05.09.25 | C22: IIL-Karkapatla | D22: IIL-Gachhibowli | E22: TG08T8450 | F22: 2MT | G22: 4900 | H22: 1000 | I22: =+H22+G22 -> 5900
... A36: 34 | B36: 11.09.25 | C36: Potential-ALEAP | D36: IIL-Karkapatla | E36: TS12UB2595 | F36: 6MT | G36: 7500 | H36: 3600 | I36: =+H36+G36 -> 11100
B37: 12.09.25 | C37: Priya feeds - Cherlapally | D37: IIL-Karkapatla | E37: TS06UA7249 | F37: 6MT | G37: 7500 | H37: 3600 | I37: =+H37+G37 -> 11100
B38: 12.09.25 | C38: Potential-ALEAP | D38: IIL-Karkapatla | E38: TS12UB2595 | F38: 6MT | G38: 7500 | H38: 3600 | I38: =+H38+G38 -> 11100
B39: 12.09.25 | C39: Gubba-Medchal | D39: IIL-Gachhibowli | E39: TG12T6078 | F39: 6MT | G39: 8500 | H39: 3600 | I39: =+H39+G39 -> 12100
B40: 12.09.25 | C40: IIL-Karkapatla | D40: IIL-Uppal | E40: TS05UA0781 | F40: 6MT | G40: 5900 | H40: 3600 | I40: =+H40+G40 -> 9500
B41: 12.09.25 | C41: Sanzyem | D41: IIL-Gachhibowli | E41: AP20TA1171 | F41: 1MT | G41: 3500 | H41: 600 | I41: =+H41+G41 -> 4100
B42: 13.09.25 | C42: Potential-ALEAP | D42: IIL-Karkapatla | E42: TG12T6078 | F42: 6MT | G42: 7500 | H42: 3600 | I42: =+H42+G42 -> 11100
B43: 15.09.25 | C43: Priya feeds - Cherlapally | D43: IIL-Karkapatla | E43: TS06UA7249 | F43: 6MT | G43: 7500 | H43: 3600 | I43: =+H43+G43 -> 11100
B44: 15.09.25 | C44: Potential-ALEAP | D44: IIL-Karkapatla | E44: TS12UB2595 | F44: 6MT | G44: 7500 | H44: 3600 | I44: =+H44+G44 -> 11100
B45: 15.09.25 | C45: Potential-ALEAP | D45: IIL-Karkapatla | E45: TS05UA0781 | F45: 6MT | G45: 7500 | H45: 3600 | I45: =+H45+G45 -> 11100
B46: 15.09.25 | C46: Gubba-Medchal | D46: IIL-Gachhibowli | E46: TG12T6078 | F46: 6MT | G46: 8500 | H46: 3600 | I46: =+H46+G46 -> 12100
B47: 15.09.25 | C47: IIL-Karkapatla | D47: IIL-Gachhibowli | E47: TS06UA7249 | F47: 6MT | G47: 6200 | H47: 3600 | I47: =+H47+G47 -> 9800
F48: Total | G48: =SUM(G3:G47) -> 306600 | H48: =SUM(H3:H47) -> 144000 | I48: =SUM(I3:I47) -> 450600
A52: Trip particulars ( 16.09.2025 to 30.09.2025)
A53: S.No. | B53: Date | C53: From Location | D53: To location | E53: Vehicle No | F53: Chargeable weight | G53: Rate | H53: Hamali | I53: Total freight
A54: 1 | B54: 16.09.26 | C54: Priya feeds - Cherlapally | D54: IIL-Karkapatla | E54: TS06UA7249 | F54: 6MT | G54: 7500 | H54: 3600 | I54: =+H54+G54 -> 11100
A55: 2 | B55: 16.09.26 | C55: Potential-ALEAP | D55: IIL-Karkapatla | E55: TS12VC3042 | F55: 6MT | G55: 7500 | H55: 3600 | I55: =+H55+G55 -> 11100
A56: 3 | B56: 16.09.26 | C56: Gubba-Medchal | D56: Potential-ALEAP | E56: TS05UA0781 | F56: 6MT | G56: 8500 | H56: 3600 | I56: =+H56+G56 -> 12100
...

Sheet Oct'25
A1: Trip particulars ( 01.10.2025 to 15.10.2025)
A2: S.No. | B2: Date | C2: From Location | D2: To location | E2: Vehicle No | F2: Chargeable weight | G2: Rate | H2: Hamali | I2: Total freight
A3: 1 | B3: 03.10.25 | C3: Potential-ALEAP | D3: IIL-Karkapatla | E3: TS06UA7249 | F3: 6MT | G3: 7500 | H3: 3600 | I3: =+H3+G3 -> 11100
A4: 2 | B4: 03.10.25 | C4: IIL-Karkapatla | D4: IIL-Uppal | E4: TG08T8450 | F4: 1MT | G4: 2800 | H4: 600 | I4: =+H4+G4 -> 3400
A5: 3 | B5: 04.10.25 | C5: IIL-Karkapatla | D5: IIL-Uppal | E5: AP20TA1171 | F5: 1MT | G5: 2800 | H5: 600 | I5: =+H5+G5 -> 3400
A6: 4 | B6: 06.10.25 | C6: Priya feeds - Cherlapally | D6: IIL-Karkapatla | E6: TG12T6078 | F6: 6MT | G6: 7500 | H6: 3600 | I6: =+H6+G6 -> 11100
A7: 5 | B7: 06.10.25 | C7: Potential-ALEAP | D7: IIL-Karkapatla | E7: TS12UB2595 | F7: 6MT | G7: 7500 | H7: 3600 | I7: =+H7+G7 -> 11100
A8: 6 | B8: 06.10.25 | C8: Potential-ALEAP | D8: IIL-Karkapatla | E8: TS12UC3042 | F8: 6MT | G8: 7500 | H8: 3600 | I8: =+H8+G8 -> 11100
A9: 7 | B9: 07.10.25 | C9: IIL-Karkapatla | D9: IIL-Uppal | E9: TG12T6078 | F9: 6MT | G9: 5900 | H9: 3600 | I9: =+H9+G9 -> 9500
A10: 8 | B10: 08.10.25 | C10: Priya feeds - Cherlapally | D10: IIL-Karkapatla | E10: TG12T6078 | F10: 6MT | G10: 7500 | H10: 3600 | I10: =+H10+G10 -> 11100
A11: 9 | B11: 08.10.25 | C11: Potential-ALEAP | D11: IIL-Karkapatla | E11: TG12UB2595 | F11: 6MT | G11: 7500 | H11: 3600 | I11: =+H11+G11 -> 11100
A12: 10 | B12: 08.10.25 | C12: Potential-ALEAP | D12: IIL-Karkapatla | E12: TS06UA7249 | F12: 6MT | G12: 7500 | H12: 3600 | I12: =+H12+G12 -> 11100
A13: 11 | B13: 08.10.25 | C13: IIL-Karkapatla | D13: IIL-Uppal | E13: TG12T6078 | F13: 6MT | G13: 5900 | H13: 3600 | I13: =+H13+G13 -> 9500
A14: 12 | B14: 08.10.25 | C14: IIL-Karkapatla | D14: IIL-Uppal | E14: TS06UA7249 | F14: 6MT | G14: 5900 | H14: 3600 | I14: =+H14+G14 -> 9500
... A33: 31 | B33: 15.10.25 | C33: IIL-Karkapatla | D33: IIL-Uppal | E33: AP20TA1171 | F33: 1MT | G33: 2800 | H33: 600 | I33: =+H33+G33 -> 3400
F34: Total | G34: =SUM(G3:G33) -> 199300 | H34: =SUM(H3:H33) -> 100200 | I34: =SUM(I3:I33) -> 299500
A38: Trip particulars ( 16.10.2025 to 31.10.2025)
A39: S.No. | B39: Date | C39: From Location | D39: To location | E39: Vehicle No | F39: Chargeable weight | G39: Rate | H39: Hamali | I39: Total freight
A40: 1 | B40: 16.10.25 | C40: Priya feeds - Cherlapally | D40: IIL-Karkapatla | E40: TG12T6078 | F40: 6MT | G40: 7500 | H40: 3600 | I40: =+H40+G40 -> 11100
A41: 2 | B41: 16.10.25 | C41: Potential-ALEAP | D41: IIL-Karkapatla | E41: TS12UB2595 | F41: 6MT | G41: 7500 | H41: 3600 | I41: =+H41+G41 -> 11100
A42: 3 | B42: 16.10.25 | C42: IIL-Karkapatla | D42: IIL-Uppal | E42: TS06UA7249 | F42: 6MT | G42: 5900 | H42: 3600 | I42: =+H42+G42 -> 9500
A43: 4 | B43: 17.10.25 | C43: IIL-Karkapatla | D43: Potential-ALEAP | E43: TG12T6078 | F43: 6MT | G43: 5800 | H43: 3600 | I43: =+H43+G43 -> 9400
A44: 5 | B44: 17.10.25 | C44: IIL-Karkapatla | D44: Potential-ALEAP | E44: TS12UC3042 | F44: 6MT | G44: 5800 | H44: 3600 | I44: =+H44+G44 -> 9400
A45: 6 | B45: 17.10.25 | C45: Potential-ALEAP | D45: IIL-Karkapatla | E45: TS06UA7249 | F45: 6MT | G45: 7500 | H45: 3600 | I45: =+H45+G45 -> 11100
A46: 7 | B46: 17.10.25 | C46: IIL-Karkapatla | D46: IIL-Gachhibowli | E46: TS12UB2595 | F46: 6MT | G46: 6200 | H46: 2400 | I46: =+H46+G46 -> 8600
A47: 8 | B47: 21.10.25 | C47: Priya feeds - Cherlapally | D47: IIL-Karkapatla | E47: TG12T6078 | F47: 6MT | G47: 7500 | H47: 3600 | I47: =+H47+G47 -> 11100
A48: 9 | B48: 21.10.25 | C48: Potential-ALEAP | D48: IIL-Karkapatla | E48: TS12UB2595 | F48: 6MT | G48: 7500 | H48: 3600 | I48: =+H48+G48 -> 11100
A49: 10 | B49: 22.10.25 | C49: Potential-ALEAP | D49: IIL-Karkapatla | E49: TG12T6078 | F49: 6MT | G49: 7500 | H49: 3600 | I49: =+H49+G49 -> 11100
A50: 11 | B50: 22.10.25 | C50: Potential-ALEAP | D50: IIL-Karkapatla | E50: TS12UB2595 | F50: 6MT | G50: 7500 | H50: 3600 | I50: =+H50+G50 -> 11100
A51: 12 | B51: 23.10.25 | C51: Priya feeds - Cherlapally | D51: IIL-Karkapatla | E51: TS05UA0781 | F51: 6MT | G51: 7500 | H51: 3600 | I51: =+H51+G51 -> 11100
... A67: 28 | B67: 29.10.25 | C67: IIL-Karkapatla | D67: IIL-Uppal | E67: TS12UB2595 | F67: 6MT | G67: 5900 | H67: 3600 | I67: =+H67+G67 -> 9500
A68: 29 | B68: 29.10.25 | C68: SANZYME | D68: IIL-Gachhibowli | E68: TG08T8450 | F68: 1MT | G68: 3500 | H68: 1200 | I68: =+H68+G68 -> 4700 | J68: KKP- Gachibowli rate considered
A69: 30 | B69: 30.10.25 | C69: IIL-Karkapatla | D69: Narsing-Ziyaguda | E69: TS12UB2595 | F69: 6MT | G69: 6200 | H69: 3600 | I69: =+H69+G69 -> 9800
A70: 31 | B70: 30.10.25 | C70: IIL-Karkapatla | D70: Ziyaguda | E70: TS12UC3042 | F70: 6MT | G70: 6200 | H70: 3600 | I70: =+H70+G70 -> 9800
A71: 32 | B71: 30.10.25 | C71: IIL-Karkapatla | D71: Potential-ALEAP | E71: TG12T6078 | F71: 6MT | G71: 5800 | H71: 3600 | I71: =+H71+G71 -> 9400
A72: 33 | B72: 30.10.25 | C72: Potential-ALEAP | D72: IIL-Karkapatla | E72: TS05UA0781 | F72: 6MT | G72: 7500 | H72: 1200 | I72: =+H72+G72 -> 8700 | J72: VEHICLE CANCELLED AT THE AFTERNOON
A73: 34 | B73: 31.10.25 | C73: IIL-Karkapatla | D73: IIL-Uppal | E73: TS12UB2595 | F73: 6MT | G73: 5900 | H73: 3600 | I73: =+H73+G73 -> 9500
A74: 35 | B74: 31.10.25 | C74: IIL-Karkapatla | D74: Potential-ALEAP | E74: TG12T6078 | F74: 6MT | G74: 7500 | H74: 3600 | I74: =+H74+G74 -> 11100
A75: 36 | B75: 31.10.25 | C75: Potential-ALEAP | D75: IIL-Karkapatla | E75: TG12T6078 | F75: 6MT | G75: 5800 | H75: 2400 | I75: =+H75+G75 -> 8200
F76: Total | G76: =SUM(G40:G75) -> 233000 | H76: =SUM(H40:H75) -> 120000 | I76: =SUM(I40:I75) -> 353000
...

Sheet Dec'25
A1: Trip particulars ( 01.12.2025 to 15.12.2025)
A2: S.No. | B2: Date | C2: From Location | D2: To location | E2: Vehicle No | F2: Chargeable weight | G2: Rate | H2: Hamali | I2: Total freight
A3: 1 | B3: 1.12.25 | C3: Priya feeds - Cherlapally | D3: IIL-Karkapatla | E3: TS12UB2595 | F3: 6MT | G3: 7500 | H3: 3600 | I3: =+H3+G3 -> 11100
A4: 2 | B4: 1.12.25 | C4: Potential-ALEAP | D4: IIL-Karkapatla | E4: TG12T6078 | F4: 6MT | G4: 7500 | H4: 3600 | I4: =+H4+G4 -> 11100
A5: 3 | B5: 1.12.25 | C5: IIL-Karkapatla | D5: Sainath-Jeedimetla | E5: TS12UB2595 | F5: 6MT | G5: 7500 | H5: 3600 | I5: =+H5+G5 -> 11100
A6: 4 | B6: 1.12.25 | C6: Sanzyme-Turkapally | D6: IIL-Karkapatla | E6: TG08T8450 | F6: 1MT | G6: 3500 | H6: 600 | I6: =+H6+G6 -> 4100
A7: 5 | B7: 2.12.25 | C7: Priya feeds - Cherlapally | D7: IIL-Karkapatla | E7: TS12UB2595 | F7: 6MT | G7: 7500 | H7: 3600 | I7: =+H7+G7 -> 11100
A8: 6 | B8: 2.12.25 | C8: IIL-Karkapatla | D8: Sainath-Jeedimetla | E8: TG12T6078 | F8: 6MT | G8: 7500 | H8: 3600 | I8: =+H8+G8 -> 11100
A9: 7 | B9: 2.12.25 | C9: Unique biotech-Turkapally | D9: IIL-Karkapatla | E9: TG08T8450 | F9: 2MT | G9: 3500 | H9: 1200 | I9: =+H9+G9 -> 4700
A10: 8 | B10: 2.12.25 | C10: IIL-Karkapatla | D10: IIL-Uppal | E10: TG08T8450 | F10: 1MT | G10: 3500 | H10: 600 | I10: =+H10+G10 -> 4100
A11: 9 | B11: 3.12.25 | C11: Potential-ALEAP | D11: IIL-Karkapatla | E11: TS12UB2595 | F11: 6MT | G11: 7500 | H11: 3600 | I11: =+H11+G11 -> 11100
A12: 10 | B12: 3.12.25 | C12: IIL-Karkapatla | D12: Sainath-Jeedimetla | E12: TG12T6078 | F12: 6MT | G12: 7500 | H12: 3600 | I12: =+H12+G12 -> 11100
A13: 11 | B13: 3.12.25 | C13: IIL-Karkapatla | D13: Sainath-Jeedimetla | E13: TS06UA7249 | F13: 6MT | G13: 7500 | H13: 3600 | I13: =+H13+G13 -> 11100
A14: 12 | B14: 3.12.25 | C14: Sainath-jeedimetla | D14: Potential-ALEAP | E14: AP22TA0164 | F14: 6MT | G14: 5900 | H14: 3600 | I14: =+H14+G14 -> 9500 | J14: Considered KKP to Uppal
A15: 13 | B15: 4.12.25 | C15: Potential-ALEAP | D15: IIL-Karkapatla | E15: TS12UB2595 | F15: 6MT | G15: 7500 | H15: 3600 | I15: =+H15+G15 -> 11100
A16: 14 | B16: 4.12.25 | C16: Potential-ALEAP | D16: IIL-Karkapatla | E16: TS12UC3042 | F16: 6MT | G16: 7500 | H16: 3600 | I16: =+H16+G16 -> 11100
A17: 15 | B17: 4.12.25 | C17: Priya feeds - Cherlapally | D17: IIL-Karkapatla | E17: TG12T6078 | F17: 6MT | G17: 7500 | H17: 3600 | I17: =+H17+G17 -> 11100
A18: 16 | B18: 4.12.25 | C18: IIL-Karkapatla | D18: Sainath-Jeedimetla | E18: TS06UA7249 | F18: 6MT | G18: 7500 | H18: 3600 | I18: =+H18+G18 -> 11100
A19: 17 | B19: 4.12.25 | C19: IIL-Karkapatla | D19: Sainath-Jeedimetla | E19: TG12T6078 | F19: 6MT | G19: 7500 | H19: 3600 | I19: =+H19+G19 -> 11100
A20: 18 | B20: 4.12.25 | C20: IIL-Karkapatla | D20: IIL-Uppal | E20: TS12UB2595 | F20: 6MT | G20: 5900 | H20: 3600 | I20: =+H20+G20 -> 9500
A21: 19 | B21: 4.12.25 | C21: Sainath-jeedimetla | D21: Potential-ALEAP | E21: TG08T8450 | F21: 3MT | G21: 4800 | H21: 1200 | I21: =+H21+G21 -> 6000
A22: 20 | B22: 5.12.25 | C22: Potential-ALEAP | D22: IIL-Karkapatla | E22: TS12UB2595 | F22: 6MT | G22: 7500 | H22: 3600 | I22: =+H22+G22 -> 11100
A23: 21 | B23: 5.12.25 | C23: IIL-Karkapatla | D23: Sainath-Jeedimetla | E23: TS06UA7249 | F23: 6MT | G23: 7500 | H23: 3600 | I23: =+H23+G23 -> 11100
A24: 22 | B24: 5.12.25 | C24: IIL-Karkapatla | D24: Sainath-Jeedimetla | E24: TG12T6078 | F24: 6MT | G24: 7500 | H24: 3600 | I24: =+H24+G24 -> 11100
A25: 23 | B25: 5.12.25 | C25: IIL-Karkapatla | D25: IIL-Uppal | E25: AP20TA1171 | F25: 1MT | G25: 3500 | H25: 600 | I25: =+H25+G25 -> 4100
A26: 24 | B26: 6.12.25 | C26: IIL-Karkapatla | D26: Sainath-Jeedimetla | E26: TS06UA7249 | F26: 6MT | G26: 7500 | H26: 3600 | I26: =+H26+G26 -> 11100
... A62: 60 | B62: 15.12.25 | C62: IIL-Karkapatla | D62: Sainath-Jeedimetla | E62: TS12UB2595 | F62: 6MT | G62: 7500 | H62: 3600 | I62: =+H62+G62 -> 11100
F63: Total | G63: =SUM(G3:G62) -> 409300 | H63: =SUM(H3:H62) -> 189700 | I63: =SUM(I3:I62) -> 599000
A67: Trip particulars ( 16.12.2025 to 31.12.2025)
A68: S.No. | B68: Date | C68: From Location | D68: To location | E68: Vehicle No | F68: Chargeable weight | G68: Rate | H68: Hamali | I68: Total freight
A69: 6 | B69: 16.12.25 | C69: IIL-Karkapatla | D69: Jiyaguda | E69: TS12UB2595 | F69: 6MT | G69: 6200 | H69: 3600 | I69: =+H69+G69 -> 9800
A70: 7 | B70: 16.12.25 | C70: IIL-Karkapatla | D70: Narsingi-Gachibowli | E70: TG12T6078 | F70: 6MT | G70: 6200 | H70: 3600 | I70: =+H70+G70 -> 9800
A71: 8 | B71: 16.12.25 | C71: IIL-Karkapatla | D71: Potential-ALEAP | E71: TS06UA7249 | F71: 6MT | G71: 5800 | H71: 3600 | I71: =+H71+G71 -> 9400
A72: 9 | B72: 16.12.25 | C72: IIL-Karkapatla | D72: IIL-Uppal | E72: AP20TA1171 | F72: 1MT | G72: 3500 | H72: 600 | I72: =+H72+G72 -> 4100
A73: 10 | B73: 17.12.25 | C73: Priya feeds - Cherlapally | D73: IIL-Karkapatla | E73: TS12UB2595 | F73: 6MT | G73: 7500 | H73: 3600 | I73: =+H73+G73 -> 11100
A74: 11 | B74: 17.12.25 | C74: Potential-ALEAP | D74: IIL-Karkapatla | E74: TG12T6078 | F74: 6MT | G74: 7500 | H74: 3600 | I74: =+H74+G74 -> 11100
A75: 12 | B75: 17.12.25 | C75: Potential-ALEAP | D75: IIL-Karkapatla | E75: TS06UA7249 | F75: 6MT | G75: 7500 | H75: 3600 | I75: =+H75+G75 -> 11100
A76: 13 | B76: 18.12.25 | C76: Priya feeds - Cherlapally | D76: IIL-Karkapatla | E76: TG12T6078 | F76: 6MT | G76: 7500 | H76: 3600 | I76: =+H76+G76 -> 11100
A77: 14 | B77: 18.12.25 | C77: IIL-Karkapatla | D77: IIL-Uppal | E77: TS12UC3042 | F77: 6MT | G77: 5900 | H77: 3600 | I77: =+H77+G77 -> 9500
A78: 15 | B78: 18.12.25 | C78: IIL-Karkapatla | D78: IIL-Uppal | E78: TS12UB2595 | F78: 6MT | G78: 5900 | H78: 3600 | I78: =+H78+G78 -> 9500
...

Sheet JAN'26
A1: Trip particulars ( 01.01.2026 to 15.01.2026)
